<?xml version="1.0" encoding="utf-8"?>
<mujoco model="actuatex_cartpole_1">
  <compiler angle="radian" autolimits="true" inertiafromgeom="false"/>
  <option timestep="0.008333333333333333" gravity="0 0 -9.81" integrator="implicitfast" iterations="20"/>
  <visual><global offwidth="1280" offheight="720"/></visual>
  <default>
    <joint armature="0.001"/>
    <geom contype="0" conaffinity="0"/>
  </default>
  <asset>
    <material name="graphite" rgba="0.075 0.085 0.10 1"/>
    <material name="orange" rgba="1.0 0.30 0.04 1"/>
    <material name="metal" rgba="0.48 0.53 0.58 1"/>
    <material name="floor" rgba="0.14 0.16 0.19 1"/>
  </asset>
  <worldbody>
    <light pos="0 -3 4" dir="0 0.4 -1" diffuse="0.9 0.9 0.9"/>
    <geom name="ground" type="plane" size="0 0 0.1" material="floor"/>
    <geom name="rail" type="box" pos="0 0 0.02" size="2.6 0.05 0.02" material="metal"/>
    <body name="cart" pos="0 0 0.16">
      <joint name="cart_slide" type="slide" axis="1 0 0" range="-2.4 2.4" damping="0.05"/>
      <inertial pos="0 0 0" mass="1.00000000" diaginertia="0.0069333333 0.0096333333 0.0123000000"/>
      <geom name="cart_visual" type="box" size="0.15 0.12 0.08" material="graphite"/>
      <body name="pole_1" pos="0 0 0.080">
        <joint name="pole_1_hinge" type="hinge" axis="0 1 0" damping="0.002"/>
        <inertial pos="0 0 0.300" mass="0.20000000" diaginertia="0.0060266667 0.0060266667 0.0000533333"/>
        <geom name="pole_1_visual" type="box" pos="0 0 0.300" size="0.020 0.020 0.300" material="orange"/>
      </body>
    </body>
  </worldbody>
  <actuator>
    <motor name="cart_force" joint="cart_slide" gear="1" ctrllimited="true" ctrlrange="-20 20"/>
  </actuator>
</mujoco>
